2023-04-12 16:12:34,895 ERROR Internal Server Error: /accounts/google/login/ C:\Users\user\AppData\Local\Programs\Python\Python38\lib\site-packages\django\utils\log.py (<class 'allauth.socialaccount.models.SocialApp.DoesNotExist'>, DoesNotExist('SocialApp matching query does not exist.'), <traceback object at 0x000002D2BA3EC3C0>)
Traceback (most recent call last):
  File "C:\Users\user\AppData\Local\Programs\Python\Python38\lib\site-packages\django\core\handlers\exception.py", line 56, in inner
    response = get_response(request)
  File "C:\Users\user\AppData\Local\Programs\Python\Python38\lib\site-packages\django\core\handlers\base.py", line 197, in _get_response
    response = wrapped_callback(request, *callback_args, **callback_kwargs)
  File "C:\Users\user\AppData\Local\Programs\Python\Python38\lib\site-packages\allauth\socialaccount\providers\oauth2\views.py", line 81, in view
    return self.dispatch(request, *args, **kwargs)
  File "C:\Users\user\AppData\Local\Programs\Python\Python38\lib\site-packages\allauth\socialaccount\providers\base\mixins.py", line 19, in dispatch
    return self.login(request, *args, **kwargs)
  File "C:\Users\user\AppData\Local\Programs\Python\Python38\lib\site-packages\allauth\socialaccount\providers\oauth2\views.py", line 109, in login
    app = provider.get_app(self.request)
  File "C:\Users\user\AppData\Local\Programs\Python\Python38\lib\site-packages\allauth\socialaccount\providers\base\provider.py", line 30, in get_app
    return adapter.get_app(request, self.id, config=config)
  File "C:\Users\user\AppData\Local\Programs\Python\Python38\lib\site-packages\allauth\socialaccount\adapter.py", line 203, in get_app
    app = SocialApp.objects.get_current(provider, request)
  File "C:\Users\user\AppData\Local\Programs\Python\Python38\lib\site-packages\allauth\socialaccount\models.py", line 31, in get_current
    app = self.get(sites__id=site.id, provider=provider)
  File "C:\Users\user\AppData\Local\Programs\Python\Python38\lib\site-packages\django\db\models\manager.py", line 85, in manager_method
    return getattr(self.get_queryset(), name)(*args, **kwargs)
  File "C:\Users\user\AppData\Local\Programs\Python\Python38\lib\site-packages\django\db\models\query.py", line 650, in get
    raise self.model.DoesNotExist(
allauth.socialaccount.models.SocialApp.DoesNotExist: SocialApp matching query does not exist.
2023-04-12 16:12:34,895 ERROR "POST /accounts/google/login/?process=login&next=%2F HTTP/1.1" 500 103443 C:\Users\user\AppData\Local\Programs\Python\Python38\lib\site-packages\django\core\servers\basehttp.py None
