2023-04-13 03:26:23,445 ERROR Internal Server Error: / C:\Users\user\AppData\Local\Programs\Python\Python38\lib\site-packages\django\utils\log.py (<class 'django.core.exceptions.FieldError'>, FieldError("Cannot resolve keyword 'date_post' into field. Choices are: author, author_id, categories, comment, content, created, id, post_type, postcategory, rating, text_post, title"), <traceback object at 0x000002602E97A0C0>)
Traceback (most recent call last):
  File "C:\Users\user\AppData\Local\Programs\Python\Python38\lib\site-packages\django\core\handlers\exception.py", line 56, in inner
    response = get_response(request)
  File "C:\Users\user\AppData\Local\Programs\Python\Python38\lib\site-packages\django\core\handlers\base.py", line 197, in _get_response
    response = wrapped_callback(request, *callback_args, **callback_kwargs)
  File "C:\Users\user\AppData\Local\Programs\Python\Python38\lib\site-packages\django\utils\decorators.py", line 134, in _wrapped_view
    response = view_func(request, *args, **kwargs)
  File "C:\Users\user\AppData\Local\Programs\Python\Python38\lib\site-packages\django\views\generic\base.py", line 103, in view
    return self.dispatch(request, *args, **kwargs)
  File "C:\Users\user\AppData\Local\Programs\Python\Python38\lib\site-packages\django\views\generic\base.py", line 142, in dispatch
    return handler(request, *args, **kwargs)
  File "C:\Users\user\AppData\Local\Programs\Python\Python38\lib\site-packages\django\views\generic\list.py", line 154, in get
    self.object_list = self.get_queryset()
  File "C:\Users\user\Desktop\NewsPortal\news\views.py", line 25, in get_queryset
    queryset = super().get_queryset()
  File "C:\Users\user\AppData\Local\Programs\Python\Python38\lib\site-packages\django\views\generic\list.py", line 45, in get_queryset
    queryset = queryset.order_by(*ordering)
  File "C:\Users\user\AppData\Local\Programs\Python\Python38\lib\site-packages\django\db\models\query.py", line 1645, in order_by
    obj.query.add_ordering(*field_names)
  File "C:\Users\user\AppData\Local\Programs\Python\Python38\lib\site-packages\django\db\models\sql\query.py", line 2202, in add_ordering
    self.names_to_path(item.split(LOOKUP_SEP), self.model._meta)
  File "C:\Users\user\AppData\Local\Programs\Python\Python38\lib\site-packages\django\db\models\sql\query.py", line 1709, in names_to_path
    raise FieldError(
django.core.exceptions.FieldError: Cannot resolve keyword 'date_post' into field. Choices are: author, author_id, categories, comment, content, created, id, post_type, postcategory, rating, text_post, title
2023-04-13 03:26:23,455 ERROR "GET / HTTP/1.1" 500 107904 C:\Users\user\AppData\Local\Programs\Python\Python38\lib\site-packages\django\core\servers\basehttp.py None
2023-04-13 03:30:02,889 ERROR Internal Server Error: / C:\Users\user\AppData\Local\Programs\Python\Python38\lib\site-packages\django\utils\log.py (<class 'django.core.exceptions.FieldError'>, FieldError("Cannot resolve keyword 'date_post' into field. Choices are: author, author_id, categories, comment, content, created, id, post_type, postcategory, rating, text_post, title"), <traceback object at 0x0000027B30BA3D00>)
Traceback (most recent call last):
  File "C:\Users\user\AppData\Local\Programs\Python\Python38\lib\site-packages\django\core\handlers\exception.py", line 56, in inner
    response = get_response(request)
  File "C:\Users\user\AppData\Local\Programs\Python\Python38\lib\site-packages\django\core\handlers\base.py", line 197, in _get_response
    response = wrapped_callback(request, *callback_args, **callback_kwargs)
  File "C:\Users\user\AppData\Local\Programs\Python\Python38\lib\site-packages\django\utils\decorators.py", line 134, in _wrapped_view
    response = view_func(request, *args, **kwargs)
  File "C:\Users\user\AppData\Local\Programs\Python\Python38\lib\site-packages\django\views\generic\base.py", line 103, in view
    return self.dispatch(request, *args, **kwargs)
  File "C:\Users\user\AppData\Local\Programs\Python\Python38\lib\site-packages\django\views\generic\base.py", line 142, in dispatch
    return handler(request, *args, **kwargs)
  File "C:\Users\user\AppData\Local\Programs\Python\Python38\lib\site-packages\django\views\generic\list.py", line 154, in get
    self.object_list = self.get_queryset()
  File "C:\Users\user\Desktop\NewsPortal\news\views.py", line 25, in get_queryset
    queryset = super().get_queryset()
  File "C:\Users\user\AppData\Local\Programs\Python\Python38\lib\site-packages\django\views\generic\list.py", line 45, in get_queryset
    queryset = queryset.order_by(*ordering)
  File "C:\Users\user\AppData\Local\Programs\Python\Python38\lib\site-packages\django\db\models\query.py", line 1645, in order_by
    obj.query.add_ordering(*field_names)
  File "C:\Users\user\AppData\Local\Programs\Python\Python38\lib\site-packages\django\db\models\sql\query.py", line 2202, in add_ordering
    self.names_to_path(item.split(LOOKUP_SEP), self.model._meta)
  File "C:\Users\user\AppData\Local\Programs\Python\Python38\lib\site-packages\django\db\models\sql\query.py", line 1709, in names_to_path
    raise FieldError(
django.core.exceptions.FieldError: Cannot resolve keyword 'date_post' into field. Choices are: author, author_id, categories, comment, content, created, id, post_type, postcategory, rating, text_post, title
2023-04-13 03:30:02,904 ERROR "GET / HTTP/1.1" 500 107683 C:\Users\user\AppData\Local\Programs\Python\Python38\lib\site-packages\django\core\servers\basehttp.py None
2023-04-13 03:30:04,477 ERROR Internal Server Error: / C:\Users\user\AppData\Local\Programs\Python\Python38\lib\site-packages\django\utils\log.py (<class 'django.core.exceptions.FieldError'>, FieldError("Cannot resolve keyword 'date_post' into field. Choices are: author, author_id, categories, comment, content, created, id, post_type, postcategory, rating, text_post, title"), <traceback object at 0x0000027B30B97380>)
Traceback (most recent call last):
  File "C:\Users\user\AppData\Local\Programs\Python\Python38\lib\site-packages\django\core\handlers\exception.py", line 56, in inner
    response = get_response(request)
  File "C:\Users\user\AppData\Local\Programs\Python\Python38\lib\site-packages\django\core\handlers\base.py", line 197, in _get_response
    response = wrapped_callback(request, *callback_args, **callback_kwargs)
  File "C:\Users\user\AppData\Local\Programs\Python\Python38\lib\site-packages\django\utils\decorators.py", line 134, in _wrapped_view
    response = view_func(request, *args, **kwargs)
  File "C:\Users\user\AppData\Local\Programs\Python\Python38\lib\site-packages\django\views\generic\base.py", line 103, in view
    return self.dispatch(request, *args, **kwargs)
  File "C:\Users\user\AppData\Local\Programs\Python\Python38\lib\site-packages\django\views\generic\base.py", line 142, in dispatch
    return handler(request, *args, **kwargs)
  File "C:\Users\user\AppData\Local\Programs\Python\Python38\lib\site-packages\django\views\generic\list.py", line 154, in get
    self.object_list = self.get_queryset()
  File "C:\Users\user\Desktop\NewsPortal\news\views.py", line 25, in get_queryset
    queryset = super().get_queryset()
  File "C:\Users\user\AppData\Local\Programs\Python\Python38\lib\site-packages\django\views\generic\list.py", line 45, in get_queryset
    queryset = queryset.order_by(*ordering)
  File "C:\Users\user\AppData\Local\Programs\Python\Python38\lib\site-packages\django\db\models\query.py", line 1645, in order_by
    obj.query.add_ordering(*field_names)
  File "C:\Users\user\AppData\Local\Programs\Python\Python38\lib\site-packages\django\db\models\sql\query.py", line 2202, in add_ordering
    self.names_to_path(item.split(LOOKUP_SEP), self.model._meta)
  File "C:\Users\user\AppData\Local\Programs\Python\Python38\lib\site-packages\django\db\models\sql\query.py", line 1709, in names_to_path
    raise FieldError(
django.core.exceptions.FieldError: Cannot resolve keyword 'date_post' into field. Choices are: author, author_id, categories, comment, content, created, id, post_type, postcategory, rating, text_post, title
2023-04-13 03:30:04,477 ERROR "GET / HTTP/1.1" 500 107683 C:\Users\user\AppData\Local\Programs\Python\Python38\lib\site-packages\django\core\servers\basehttp.py None
2023-04-13 03:30:05,495 ERROR Internal Server Error: / C:\Users\user\AppData\Local\Programs\Python\Python38\lib\site-packages\django\utils\log.py (<class 'django.core.exceptions.FieldError'>, FieldError("Cannot resolve keyword 'date_post' into field. Choices are: author, author_id, categories, comment, content, created, id, post_type, postcategory, rating, text_post, title"), <traceback object at 0x0000027B30EA7980>)
Traceback (most recent call last):
  File "C:\Users\user\AppData\Local\Programs\Python\Python38\lib\site-packages\django\core\handlers\exception.py", line 56, in inner
    response = get_response(request)
  File "C:\Users\user\AppData\Local\Programs\Python\Python38\lib\site-packages\django\core\handlers\base.py", line 197, in _get_response
    response = wrapped_callback(request, *callback_args, **callback_kwargs)
  File "C:\Users\user\AppData\Local\Programs\Python\Python38\lib\site-packages\django\utils\decorators.py", line 134, in _wrapped_view
    response = view_func(request, *args, **kwargs)
  File "C:\Users\user\AppData\Local\Programs\Python\Python38\lib\site-packages\django\views\generic\base.py", line 103, in view
    return self.dispatch(request, *args, **kwargs)
  File "C:\Users\user\AppData\Local\Programs\Python\Python38\lib\site-packages\django\views\generic\base.py", line 142, in dispatch
    return handler(request, *args, **kwargs)
  File "C:\Users\user\AppData\Local\Programs\Python\Python38\lib\site-packages\django\views\generic\list.py", line 154, in get
    self.object_list = self.get_queryset()
  File "C:\Users\user\Desktop\NewsPortal\news\views.py", line 25, in get_queryset
    queryset = super().get_queryset()
  File "C:\Users\user\AppData\Local\Programs\Python\Python38\lib\site-packages\django\views\generic\list.py", line 45, in get_queryset
    queryset = queryset.order_by(*ordering)
  File "C:\Users\user\AppData\Local\Programs\Python\Python38\lib\site-packages\django\db\models\query.py", line 1645, in order_by
    obj.query.add_ordering(*field_names)
  File "C:\Users\user\AppData\Local\Programs\Python\Python38\lib\site-packages\django\db\models\sql\query.py", line 2202, in add_ordering
    self.names_to_path(item.split(LOOKUP_SEP), self.model._meta)
  File "C:\Users\user\AppData\Local\Programs\Python\Python38\lib\site-packages\django\db\models\sql\query.py", line 1709, in names_to_path
    raise FieldError(
django.core.exceptions.FieldError: Cannot resolve keyword 'date_post' into field. Choices are: author, author_id, categories, comment, content, created, id, post_type, postcategory, rating, text_post, title
2023-04-13 03:30:05,511 ERROR "GET / HTTP/1.1" 500 107683 C:\Users\user\AppData\Local\Programs\Python\Python38\lib\site-packages\django\core\servers\basehttp.py None
2023-04-13 03:30:06,197 ERROR Internal Server Error: / C:\Users\user\AppData\Local\Programs\Python\Python38\lib\site-packages\django\utils\log.py (<class 'django.core.exceptions.FieldError'>, FieldError("Cannot resolve keyword 'date_post' into field. Choices are: author, author_id, categories, comment, content, created, id, post_type, postcategory, rating, text_post, title"), <traceback object at 0x0000027B30EA76C0>)
Traceback (most recent call last):
  File "C:\Users\user\AppData\Local\Programs\Python\Python38\lib\site-packages\django\core\handlers\exception.py", line 56, in inner
    response = get_response(request)
  File "C:\Users\user\AppData\Local\Programs\Python\Python38\lib\site-packages\django\core\handlers\base.py", line 197, in _get_response
    response = wrapped_callback(request, *callback_args, **callback_kwargs)
  File "C:\Users\user\AppData\Local\Programs\Python\Python38\lib\site-packages\django\utils\decorators.py", line 134, in _wrapped_view
    response = view_func(request, *args, **kwargs)
  File "C:\Users\user\AppData\Local\Programs\Python\Python38\lib\site-packages\django\views\generic\base.py", line 103, in view
    return self.dispatch(request, *args, **kwargs)
  File "C:\Users\user\AppData\Local\Programs\Python\Python38\lib\site-packages\django\views\generic\base.py", line 142, in dispatch
    return handler(request, *args, **kwargs)
  File "C:\Users\user\AppData\Local\Programs\Python\Python38\lib\site-packages\django\views\generic\list.py", line 154, in get
    self.object_list = self.get_queryset()
  File "C:\Users\user\Desktop\NewsPortal\news\views.py", line 25, in get_queryset
    queryset = super().get_queryset()
  File "C:\Users\user\AppData\Local\Programs\Python\Python38\lib\site-packages\django\views\generic\list.py", line 45, in get_queryset
    queryset = queryset.order_by(*ordering)
  File "C:\Users\user\AppData\Local\Programs\Python\Python38\lib\site-packages\django\db\models\query.py", line 1645, in order_by
    obj.query.add_ordering(*field_names)
  File "C:\Users\user\AppData\Local\Programs\Python\Python38\lib\site-packages\django\db\models\sql\query.py", line 2202, in add_ordering
    self.names_to_path(item.split(LOOKUP_SEP), self.model._meta)
  File "C:\Users\user\AppData\Local\Programs\Python\Python38\lib\site-packages\django\db\models\sql\query.py", line 1709, in names_to_path
    raise FieldError(
django.core.exceptions.FieldError: Cannot resolve keyword 'date_post' into field. Choices are: author, author_id, categories, comment, content, created, id, post_type, postcategory, rating, text_post, title
2023-04-13 03:30:06,197 ERROR "GET / HTTP/1.1" 500 107683 C:\Users\user\AppData\Local\Programs\Python\Python38\lib\site-packages\django\core\servers\basehttp.py None
2023-04-13 03:30:06,899 ERROR Internal Server Error: / C:\Users\user\AppData\Local\Programs\Python\Python38\lib\site-packages\django\utils\log.py (<class 'django.core.exceptions.FieldError'>, FieldError("Cannot resolve keyword 'date_post' into field. Choices are: author, author_id, categories, comment, content, created, id, post_type, postcategory, rating, text_post, title"), <traceback object at 0x0000027B30F2CD00>)
Traceback (most recent call last):
  File "C:\Users\user\AppData\Local\Programs\Python\Python38\lib\site-packages\django\core\handlers\exception.py", line 56, in inner
    response = get_response(request)
  File "C:\Users\user\AppData\Local\Programs\Python\Python38\lib\site-packages\django\core\handlers\base.py", line 197, in _get_response
    response = wrapped_callback(request, *callback_args, **callback_kwargs)
  File "C:\Users\user\AppData\Local\Programs\Python\Python38\lib\site-packages\django\utils\decorators.py", line 134, in _wrapped_view
    response = view_func(request, *args, **kwargs)
  File "C:\Users\user\AppData\Local\Programs\Python\Python38\lib\site-packages\django\views\generic\base.py", line 103, in view
    return self.dispatch(request, *args, **kwargs)
  File "C:\Users\user\AppData\Local\Programs\Python\Python38\lib\site-packages\django\views\generic\base.py", line 142, in dispatch
    return handler(request, *args, **kwargs)
  File "C:\Users\user\AppData\Local\Programs\Python\Python38\lib\site-packages\django\views\generic\list.py", line 154, in get
    self.object_list = self.get_queryset()
  File "C:\Users\user\Desktop\NewsPortal\news\views.py", line 25, in get_queryset
    queryset = super().get_queryset()
  File "C:\Users\user\AppData\Local\Programs\Python\Python38\lib\site-packages\django\views\generic\list.py", line 45, in get_queryset
    queryset = queryset.order_by(*ordering)
  File "C:\Users\user\AppData\Local\Programs\Python\Python38\lib\site-packages\django\db\models\query.py", line 1645, in order_by
    obj.query.add_ordering(*field_names)
  File "C:\Users\user\AppData\Local\Programs\Python\Python38\lib\site-packages\django\db\models\sql\query.py", line 2202, in add_ordering
    self.names_to_path(item.split(LOOKUP_SEP), self.model._meta)
  File "C:\Users\user\AppData\Local\Programs\Python\Python38\lib\site-packages\django\db\models\sql\query.py", line 1709, in names_to_path
    raise FieldError(
django.core.exceptions.FieldError: Cannot resolve keyword 'date_post' into field. Choices are: author, author_id, categories, comment, content, created, id, post_type, postcategory, rating, text_post, title
2023-04-13 03:30:06,914 ERROR "GET / HTTP/1.1" 500 107683 C:\Users\user\AppData\Local\Programs\Python\Python38\lib\site-packages\django\core\servers\basehttp.py None
2023-04-13 03:31:35,624 ERROR Internal Server Error: / C:\Users\user\AppData\Local\Programs\Python\Python38\lib\site-packages\django\utils\log.py (<class 'django.core.exceptions.FieldError'>, FieldError("Cannot resolve keyword 'date_post' into field. Choices are: author, author_id, categories, comment, content, created, id, post_type, postcategory, rating, text_post, title"), <traceback object at 0x000001EC15C866C0>)
Traceback (most recent call last):
  File "C:\Users\user\AppData\Local\Programs\Python\Python38\lib\site-packages\django\core\handlers\exception.py", line 56, in inner
    response = get_response(request)
  File "C:\Users\user\AppData\Local\Programs\Python\Python38\lib\site-packages\django\core\handlers\base.py", line 197, in _get_response
    response = wrapped_callback(request, *callback_args, **callback_kwargs)
  File "C:\Users\user\AppData\Local\Programs\Python\Python38\lib\site-packages\django\utils\decorators.py", line 134, in _wrapped_view
    response = view_func(request, *args, **kwargs)
  File "C:\Users\user\AppData\Local\Programs\Python\Python38\lib\site-packages\django\views\generic\base.py", line 103, in view
    return self.dispatch(request, *args, **kwargs)
  File "C:\Users\user\AppData\Local\Programs\Python\Python38\lib\site-packages\django\views\generic\base.py", line 142, in dispatch
    return handler(request, *args, **kwargs)
  File "C:\Users\user\AppData\Local\Programs\Python\Python38\lib\site-packages\django\views\generic\list.py", line 154, in get
    self.object_list = self.get_queryset()
  File "C:\Users\user\Desktop\NewsPortal\news\views.py", line 25, in get_queryset
    queryset = super().get_queryset()
  File "C:\Users\user\AppData\Local\Programs\Python\Python38\lib\site-packages\django\views\generic\list.py", line 45, in get_queryset
    queryset = queryset.order_by(*ordering)
  File "C:\Users\user\AppData\Local\Programs\Python\Python38\lib\site-packages\django\db\models\query.py", line 1645, in order_by
    obj.query.add_ordering(*field_names)
  File "C:\Users\user\AppData\Local\Programs\Python\Python38\lib\site-packages\django\db\models\sql\query.py", line 2202, in add_ordering
    self.names_to_path(item.split(LOOKUP_SEP), self.model._meta)
  File "C:\Users\user\AppData\Local\Programs\Python\Python38\lib\site-packages\django\db\models\sql\query.py", line 1709, in names_to_path
    raise FieldError(
django.core.exceptions.FieldError: Cannot resolve keyword 'date_post' into field. Choices are: author, author_id, categories, comment, content, created, id, post_type, postcategory, rating, text_post, title
2023-04-13 03:31:35,656 ERROR "GET / HTTP/1.1" 500 107683 C:\Users\user\AppData\Local\Programs\Python\Python38\lib\site-packages\django\core\servers\basehttp.py None
2023-04-13 03:37:27,908 ERROR Internal Server Error: / C:\Users\user\AppData\Local\Programs\Python\Python38\lib\site-packages\django\utils\log.py (<class 'django.db.utils.OperationalError'>, OperationalError('no such table: news_post'), <traceback object at 0x0000021EFB4BFA00>)
Traceback (most recent call last):
  File "C:\Users\user\AppData\Local\Programs\Python\Python38\lib\site-packages\django\db\backends\utils.py", line 89, in _execute
    return self.cursor.execute(sql, params)
  File "C:\Users\user\AppData\Local\Programs\Python\Python38\lib\site-packages\django\db\backends\sqlite3\base.py", line 357, in execute
    return Database.Cursor.execute(self, query, params)
sqlite3.OperationalError: no such table: news_post

The above exception was the direct cause of the following exception:

Traceback (most recent call last):
  File "C:\Users\user\AppData\Local\Programs\Python\Python38\lib\site-packages\django\core\handlers\exception.py", line 56, in inner
    response = get_response(request)
  File "C:\Users\user\AppData\Local\Programs\Python\Python38\lib\site-packages\django\core\handlers\base.py", line 197, in _get_response
    response = wrapped_callback(request, *callback_args, **callback_kwargs)
  File "C:\Users\user\AppData\Local\Programs\Python\Python38\lib\site-packages\django\utils\decorators.py", line 134, in _wrapped_view
    response = view_func(request, *args, **kwargs)
  File "C:\Users\user\AppData\Local\Programs\Python\Python38\lib\site-packages\django\views\generic\base.py", line 103, in view
    return self.dispatch(request, *args, **kwargs)
  File "C:\Users\user\AppData\Local\Programs\Python\Python38\lib\site-packages\django\views\generic\base.py", line 142, in dispatch
    return handler(request, *args, **kwargs)
  File "C:\Users\user\AppData\Local\Programs\Python\Python38\lib\site-packages\django\views\generic\list.py", line 174, in get
    context = self.get_context_data()
  File "C:\Users\user\Desktop\NewsPortal\news\views.py", line 29, in get_context_data
    context = super().get_context_data(**kwargs)
  File "C:\Users\user\AppData\Local\Programs\Python\Python38\lib\site-packages\django\views\generic\list.py", line 128, in get_context_data
    paginator, page, queryset, is_paginated = self.paginate_queryset(
  File "C:\Users\user\AppData\Local\Programs\Python\Python38\lib\site-packages\django\views\generic\list.py", line 73, in paginate_queryset
    page = paginator.page(page_number)
  File "C:\Users\user\AppData\Local\Programs\Python\Python38\lib\site-packages\django\core\paginator.py", line 75, in page
    number = self.validate_number(number)
  File "C:\Users\user\AppData\Local\Programs\Python\Python38\lib\site-packages\django\core\paginator.py", line 53, in validate_number
    if number > self.num_pages:
  File "C:\Users\user\AppData\Local\Programs\Python\Python38\lib\site-packages\django\utils\functional.py", line 57, in __get__
    res = instance.__dict__[self.name] = self.func(instance)
  File "C:\Users\user\AppData\Local\Programs\Python\Python38\lib\site-packages\django\core\paginator.py", line 102, in num_pages
    if self.count == 0 and not self.allow_empty_first_page:
  File "C:\Users\user\AppData\Local\Programs\Python\Python38\lib\site-packages\django\utils\functional.py", line 57, in __get__
    res = instance.__dict__[self.name] = self.func(instance)
  File "C:\Users\user\AppData\Local\Programs\Python\Python38\lib\site-packages\django\core\paginator.py", line 96, in count
    return c()
  File "C:\Users\user\AppData\Local\Programs\Python\Python38\lib\site-packages\django\db\models\query.py", line 621, in count
    return self.query.get_count(using=self.db)
  File "C:\Users\user\AppData\Local\Programs\Python\Python38\lib\site-packages\django\db\models\sql\query.py", line 559, in get_count
    return obj.get_aggregation(using, ["__count"])["__count"]
  File "C:\Users\user\AppData\Local\Programs\Python\Python38\lib\site-packages\django\db\models\sql\query.py", line 544, in get_aggregation
    result = compiler.execute_sql(SINGLE)
  File "C:\Users\user\AppData\Local\Programs\Python\Python38\lib\site-packages\django\db\models\sql\compiler.py", line 1398, in execute_sql
    cursor.execute(sql, params)
  File "C:\Users\user\AppData\Local\Programs\Python\Python38\lib\site-packages\django\db\backends\utils.py", line 102, in execute
    return super().execute(sql, params)
  File "C:\Users\user\AppData\Local\Programs\Python\Python38\lib\site-packages\django\db\backends\utils.py", line 67, in execute
    return self._execute_with_wrappers(
  File "C:\Users\user\AppData\Local\Programs\Python\Python38\lib\site-packages\django\db\backends\utils.py", line 80, in _execute_with_wrappers
    return executor(sql, params, many, context)
  File "C:\Users\user\AppData\Local\Programs\Python\Python38\lib\site-packages\django\db\backends\utils.py", line 89, in _execute
    return self.cursor.execute(sql, params)
  File "C:\Users\user\AppData\Local\Programs\Python\Python38\lib\site-packages\django\db\utils.py", line 91, in __exit__
    raise dj_exc_value.with_traceback(traceback) from exc_value
  File "C:\Users\user\AppData\Local\Programs\Python\Python38\lib\site-packages\django\db\backends\utils.py", line 89, in _execute
    return self.cursor.execute(sql, params)
  File "C:\Users\user\AppData\Local\Programs\Python\Python38\lib\site-packages\django\db\backends\sqlite3\base.py", line 357, in execute
    return Database.Cursor.execute(self, query, params)
django.db.utils.OperationalError: no such table: news_post
2023-04-13 03:37:27,942 ERROR "GET / HTTP/1.1" 500 179741 C:\Users\user\AppData\Local\Programs\Python\Python38\lib\site-packages\django\core\servers\basehttp.py None
2023-04-13 03:40:14,573 ERROR Internal Server Error: / C:\Users\user\AppData\Local\Programs\Python\Python38\lib\site-packages\django\utils\log.py (<class 'django.db.utils.OperationalError'>, OperationalError('no such table: news_post'), <traceback object at 0x0000025221756880>)
Traceback (most recent call last):
  File "C:\Users\user\AppData\Local\Programs\Python\Python38\lib\site-packages\django\db\backends\utils.py", line 89, in _execute
    return self.cursor.execute(sql, params)
  File "C:\Users\user\AppData\Local\Programs\Python\Python38\lib\site-packages\django\db\backends\sqlite3\base.py", line 357, in execute
    return Database.Cursor.execute(self, query, params)
sqlite3.OperationalError: no such table: news_post

The above exception was the direct cause of the following exception:

Traceback (most recent call last):
  File "C:\Users\user\AppData\Local\Programs\Python\Python38\lib\site-packages\django\core\handlers\exception.py", line 56, in inner
    response = get_response(request)
  File "C:\Users\user\AppData\Local\Programs\Python\Python38\lib\site-packages\django\core\handlers\base.py", line 197, in _get_response
    response = wrapped_callback(request, *callback_args, **callback_kwargs)
  File "C:\Users\user\AppData\Local\Programs\Python\Python38\lib\site-packages\django\utils\decorators.py", line 134, in _wrapped_view
    response = view_func(request, *args, **kwargs)
  File "C:\Users\user\AppData\Local\Programs\Python\Python38\lib\site-packages\django\views\generic\base.py", line 103, in view
    return self.dispatch(request, *args, **kwargs)
  File "C:\Users\user\AppData\Local\Programs\Python\Python38\lib\site-packages\django\views\generic\base.py", line 142, in dispatch
    return handler(request, *args, **kwargs)
  File "C:\Users\user\AppData\Local\Programs\Python\Python38\lib\site-packages\django\views\generic\list.py", line 174, in get
    context = self.get_context_data()
  File "C:\Users\user\Desktop\NewsPortal\news\views.py", line 29, in get_context_data
    context = super().get_context_data(**kwargs)
  File "C:\Users\user\AppData\Local\Programs\Python\Python38\lib\site-packages\django\views\generic\list.py", line 128, in get_context_data
    paginator, page, queryset, is_paginated = self.paginate_queryset(
  File "C:\Users\user\AppData\Local\Programs\Python\Python38\lib\site-packages\django\views\generic\list.py", line 73, in paginate_queryset
    page = paginator.page(page_number)
  File "C:\Users\user\AppData\Local\Programs\Python\Python38\lib\site-packages\django\core\paginator.py", line 75, in page
    number = self.validate_number(number)
  File "C:\Users\user\AppData\Local\Programs\Python\Python38\lib\site-packages\django\core\paginator.py", line 53, in validate_number
    if number > self.num_pages:
  File "C:\Users\user\AppData\Local\Programs\Python\Python38\lib\site-packages\django\utils\functional.py", line 57, in __get__
    res = instance.__dict__[self.name] = self.func(instance)
  File "C:\Users\user\AppData\Local\Programs\Python\Python38\lib\site-packages\django\core\paginator.py", line 102, in num_pages
    if self.count == 0 and not self.allow_empty_first_page:
  File "C:\Users\user\AppData\Local\Programs\Python\Python38\lib\site-packages\django\utils\functional.py", line 57, in __get__
    res = instance.__dict__[self.name] = self.func(instance)
  File "C:\Users\user\AppData\Local\Programs\Python\Python38\lib\site-packages\django\core\paginator.py", line 96, in count
    return c()
  File "C:\Users\user\AppData\Local\Programs\Python\Python38\lib\site-packages\django\db\models\query.py", line 621, in count
    return self.query.get_count(using=self.db)
  File "C:\Users\user\AppData\Local\Programs\Python\Python38\lib\site-packages\django\db\models\sql\query.py", line 559, in get_count
    return obj.get_aggregation(using, ["__count"])["__count"]
  File "C:\Users\user\AppData\Local\Programs\Python\Python38\lib\site-packages\django\db\models\sql\query.py", line 544, in get_aggregation
    result = compiler.execute_sql(SINGLE)
  File "C:\Users\user\AppData\Local\Programs\Python\Python38\lib\site-packages\django\db\models\sql\compiler.py", line 1398, in execute_sql
    cursor.execute(sql, params)
  File "C:\Users\user\AppData\Local\Programs\Python\Python38\lib\site-packages\django\db\backends\utils.py", line 102, in execute
    return super().execute(sql, params)
  File "C:\Users\user\AppData\Local\Programs\Python\Python38\lib\site-packages\django\db\backends\utils.py", line 67, in execute
    return self._execute_with_wrappers(
  File "C:\Users\user\AppData\Local\Programs\Python\Python38\lib\site-packages\django\db\backends\utils.py", line 80, in _execute_with_wrappers
    return executor(sql, params, many, context)
  File "C:\Users\user\AppData\Local\Programs\Python\Python38\lib\site-packages\django\db\backends\utils.py", line 89, in _execute
    return self.cursor.execute(sql, params)
  File "C:\Users\user\AppData\Local\Programs\Python\Python38\lib\site-packages\django\db\utils.py", line 91, in __exit__
    raise dj_exc_value.with_traceback(traceback) from exc_value
  File "C:\Users\user\AppData\Local\Programs\Python\Python38\lib\site-packages\django\db\backends\utils.py", line 89, in _execute
    return self.cursor.execute(sql, params)
  File "C:\Users\user\AppData\Local\Programs\Python\Python38\lib\site-packages\django\db\backends\sqlite3\base.py", line 357, in execute
    return Database.Cursor.execute(self, query, params)
django.db.utils.OperationalError: no such table: news_post
2023-04-13 03:40:14,604 ERROR "GET / HTTP/1.1" 500 179741 C:\Users\user\AppData\Local\Programs\Python\Python38\lib\site-packages\django\core\servers\basehttp.py None
